# SOME DESCRIPTIVE TITLE.
# Copyright (C) YEAR THE PACKAGE'S COPYRIGHT HOLDER
# This file is distributed under the same license as the PACKAGE package.
#
# Translators:
# Hirofumi Saito <hi_saito@yk.rim.or.jp>, 2004.
# kiyoto james hashida <khashida@brisbane.redhat.com>, 2007.
# Kiyoto James Hashida <khashida@redhat.com>, 2006.
# Noriko Mizumoto <noriko@redhat.com>, 2004-2007.
# noriko <noriko@fedoraproject.org>, 2011.
# Tadashi Jokagi <fedora@elf.no-ip.org>, 2005.
# Yukihiro Nakai <ynakai@redhat.com>, 2001.
# Jiri Dostal <jdostal@redhat.com>, 2018. #zanata
msgid ""
msgstr ""
"Project-Id-Version: Spacewalk\n"
"Report-Msgid-Bugs-To: \n"
"POT-Creation-Date: 2020-09-29 14:21+0200\n"
"PO-Revision-Date: 2020-09-26 01:48+0000\n"
"Last-Translator: Yasuhiko Kamata <belphegor@belbel.or.jp>\n"
"Language-Team: Japanese <https://l10n.opensuse.org/projects/uyuni/backend/ja/"
">\n"
"Language: ja\n"
"MIME-Version: 1.0\n"
"Content-Type: text/plain; charset=UTF-8\n"
"Content-Transfer-Encoding: 8bit\n"
"Plural-Forms: nplurals=1; plural=0;\n"
"X-Generator: Weblate 3.6.1\n"

#: ../server/apacheAuth.py:66
#, python-format
msgid "incomplete proxy authentication token: %s"
msgstr "不完全なプロキシ認証トークンです: %s"

#: ../server/apacheAuth.py:84
#, python-format
msgid "Sent proxy signature %s does not match ours %s."
msgstr "送信されたプロキシ署名 %s がこちら側の %s と一致しません。"

#: ../server/apacheAuth.py:119
msgid "declined proxy authentication"
msgstr "プロキシ認証が拒否されました"

#: ../server/handlers/app/packages.py:192
#: ../server/handlers/xmlrpc/registration.py:215
#: ../server/handlers/xmlrpc/registration.py:1168
#: ../server/handlers/xmlrpc/registration.py:1307
#: ../server/configFilesHandler.py:129
#, python-format
msgid ""
"\n"
"                   %s Account has been deactivated on this server.\n"
"                   Please contact your Org administrator for more help."
msgstr ""
"\n"
"                   %s アカウントは本サーバー上では非アクティブになっていま"
"す。\n"
"                   組織の管理者にお問い合わせください。"

#: ../server/handlers/applet/applet.py:78
#, python-brace-format
msgid "Your system was not found in the {PRODUCT_NAME} database"
msgstr "システムが {PRODUCT_NAME} データベース内には見つかりませんでした"

#: ../server/handlers/sat/auth.py:45
msgid "ISS is disabled on this server."
msgstr "このサーバでは ISS が無効化されています。"

#: ../server/handlers/sat/auth.py:50
#, python-format
msgid "Server \"%s\" is not enabled for ISS."
msgstr "サーバー「%s」は ISS に有効になっていません。"

#: ../server/handlers/xmlrpc/scap.py:104
msgid "Invalid system_id/action_id pair."
msgstr "system_id/action_id の対が正しくありません。"

#: ../server/handlers/xmlrpc/errata.py:64
#, python-format
msgid "Expected a package name, not: %s"
msgstr "パッケージ名が期待されています、次ではありません: %s"

#: ../server/handlers/xmlrpc/errata.py:115
#, python-format
msgid "Expected a package, not: %s"
msgstr "パッケージが期待されています、 次ではありません: %s"

#: ../server/handlers/xmlrpc/queue.py:433
#, python-format
msgid "Invalid action value type %s (%s)"
msgstr "無効な動作値タイプ %s (%s)"

#: ../server/handlers/xmlrpc/queue.py:464
#, python-format
msgid "Action %s does not belong to server %s"
msgstr "動作 %s はサーバー %s に属していません"

#: ../server/handlers/xmlrpc/up2date.py:233
#, python-format
msgid "Invalid value %s (%s)"
msgstr "無効な値  %s (%s)"

#: ../server/handlers/xmlrpc/proxy.py:65
#, python-format
msgid "SUSE Manager Proxy service not enabled for server profile: \"%s\""
msgstr ""
"サーバプロファイルに対して SUSE Manager Proxy サービスが有効化されていませ"
"ん: \"%s\""

#: ../server/handlers/xmlrpc/proxy.py:85
msgid "Invalid session key"
msgstr "無効なセッションキー"

#: ../server/handlers/xmlrpc/proxy.py:93
msgid "This server ID no longer exists"
msgstr "このサーバー ID は既になくなりました"

#: ../server/handlers/xmlrpc/registration.py:194
msgid "Required data missing"
msgstr "必要なデータが足りません"

#: ../server/handlers/xmlrpc/registration.py:198
msgid "Required members missing"
msgstr "必要なメンバーが足りません"

#: ../server/handlers/xmlrpc/registration.py:207
msgid "Attempt to register a system to an invalid username"
msgstr "システムを無効なユーザー名に登録しようとしています"

#: ../server/handlers/xmlrpc/registration.py:839
msgid "Invalid system release version requested"
msgstr "無効なシステムリリースバージョンを要求しています"

#: ../server/handlers/xmlrpc/registration.py:1063
msgid ""
"Unable to find a valid network interface, both ipaddr and ip6addr not found."
msgstr ""
"適切なネットワークインターフェイスが見つかりませんでした。 ipaddr と ip6addr "
"の両方が見つかりません。"

#: ../server/handlers/xmlrpc/registration.py:1115
#, python-brace-format
msgid "{PRODUCT_NAME} Welcome Message"
msgstr "{PRODUCT_NAME} ようこそメッセージ"

#: ../server/handlers/xmlrpc/registration.py:1125
msgid "Privacy Statement"
msgstr "プライバシーステートメント"

#: ../server/handlers/xmlrpc/registration.py:1146
msgid "Expected a dictionary as a product argument"
msgstr "製品の引数としてディクショナリが期待されています"

#: ../server/handlers/xmlrpc/registration.py:1374
#, python-format
msgid "Invalid value '%s' for %s (%s)"
msgstr "無効な値 '%s' − %s (%s)"

#: ../server/importlib/userAuth.py:98
msgid "You are not authorized to manage packages in the null org"
msgstr "null org にあるパッケージを管理する権限が与えられていません"

#: ../server/importlib/userAuth.py:103
#, python-format
msgid "You are not allowed to manage packages in the %s org"
msgstr "%s org 内のパッケージの管理は許可されていません"

#: ../server/importlib/userAuth.py:121
msgid "You are not allowed to perform administrative tasks"
msgstr "管理に関する作業を行う許可がありません"

#: ../server/importlib/userAuth.py:144
#, python-format
msgid ""
"You are not allowed to manage channel %s, or that channel does not exist"
msgstr ""
"チャンネル %s の管理は許可されていないか、 またはこのチャンネルは存在していま"
"せん"

#: ../server/importlib/userAuth.py:204
#, python-format
msgid ""
"\n"
"               %s Account has been deactivated on this server.\n"
"               Please contact your Org administrator for more help."
msgstr ""
"\n"
"               %s アカウントは本サーバー上では無効化されています。\n"
"                   詳しくは組織の管理者にお問い合わせください。"

#: ../server/rhnHandler.py:62
msgid "Please run rhn_register as root on this client"
msgstr ""
"このクライアント上で root ユーザーになり、 rhn_register を実行してください"

#: ../server/rhnHandler.py:75
#, python-format
msgid "Service not enabled for system profile: \"%s\""
msgstr "システムプロファイルに対してサービスが有効になっていません: 「%s」"

#: ../server/rhnServer/server_class.py:97
#, python-format
msgid "Architecture `%s' is not supported"
msgstr "アーキテクチャ `%s' はサポートされていません"

#: ../server/rhnServer/server_token.py:78
#, python-format
msgid "Token `%s' has more than one base channel assigned"
msgstr "トークン `%s' には 1 つ以上のベースチャンネルが割り当てられています"

#: ../server/rhnServer/server_token.py:80
msgid "Conflicting base channels"
msgstr "競合しているベースチャンネル"

#: ../server/rhnServer/server_token.py:190
#, python-format
msgid "Failed to add server to group %s"
msgstr "グループ %s へのサーバーの追加に失敗しました"

#: ../server/rhnServer/server_token.py:503
#, python-format
msgid "Maximum usage count of %s reached"
msgstr "最大使用数 %s に達しました"

#: ../server/rhnServer/server_token.py:744
msgid ""
"Stacking of re-registration tokens with different base entitlements is not "
"supported"
msgstr ""
"異なるベースエンタイトルメントでの再登録トークンの積み重ねには対応していませ"
"ん"

#: ../server/rhnServer/server_token.py:811
#, python-format
msgid "Could not find token '%s'"
msgstr "トークン「%s」は見つかりませんでした"

#. Cannot use activation keys from different orgs
#: ../server/rhnServer/server_token.py:843
msgid "Tokens from mismatching orgs"
msgstr "不一致の 　org からのトークンです"

#. Two tokens with different kickstart sessions
#: ../server/rhnServer/server_token.py:853
msgid "Kickstart session mismatch"
msgstr "キックスタートセッションの不一致です"

#: ../server/rhnServer/server_token.py:877
msgid "Stacking of re-registration tokens is not supported"
msgstr "再登録トークンの積み重ねには対応していません"

#: ../server/rhnUser.py:289 ../server/rhnUser.py:292
msgid "Invalid username/password combination"
msgstr "無効なユーザー名とパスワードの組み合わせです"

#. nope, not reserved either
#: ../server/rhnUser.py:467
#, python-format
msgid "Username `%s' has not been reserved"
msgstr "ユーザー名 `%s' は予約されていません"

#. New accounts have to specify an e-mail address
#: ../server/rhnUser.py:473
msgid "E-mail address not specified"
msgstr "Email アドレスが指定されていません"

#: ../server/rhnUser.py:509
#, python-format
msgid "username should be at least %d characters"
msgstr "ユーザー名は少なくとも %d 文字以上にしてください"

#: ../server/rhnUser.py:512
#, python-format
msgid "username should be less than %d characters"
msgstr "ユーザー名は %d 文字未満にしてください"

#: ../server/rhnUser.py:523
#, python-format
msgid "username = `%s', invalid character `%s'"
msgstr "ユーザー名 = `%s'、 無効な文字 `%s'"

#: ../server/rhnUser.py:542
#, python-format
msgid "Please limit your e-mail address to %s chars"
msgstr "Email アドレスは %s 文字以内にしてください"

#: ../server/rhnUser.py:623
#, python-format
msgid "password must be at least %d characters"
msgstr "パスワードは少なくとも %d 文字に以上にしてください"

#: ../server/rhnUser.py:626
#, python-format
msgid "Password must be shorter than %d characters"
msgstr "パスワードは %d 文字以内にしてください"

#: ../server/rhnUser.py:644
#, python-format
msgid "password contains character `%s'"
msgstr "パスワードに `%s' 文字が含まれています"

#: ../server/rhnUser.py:651
#, python-format
msgid "username should be at least %d characters long"
msgstr "ユーザー名は少なくとも %d 文字以上の長さにしてください"

#: ../server/rhnUser.py:662
#, python-format
msgid "Cannot register usernames ending with %s"
msgstr "%s で終わるユーザー名は登録できません"

#: ../server/rhnPackage.py:49 ../server/rhnPackage.py:87
#: ../server/rhnPackage.py:107 ../server/rhnPackage.py:158
#, python-format
msgid "Invalid RPM package %s requested"
msgstr "無効な RPM パッケージ %s を要求しています"

#: ../server/rhnPackage.py:112
msgid "Package not found"
msgstr "パッケージが見つかりません"

#: ../server/apacheRequest.py:59
#, python-format
msgid "Invalid request received (%s)."
msgstr "無効な要求を受け取りました (%s)。"

#: ../server/apacheRequest.py:120
#, python-format
msgid ""
"IMPORTANT MESSAGE FOLLOWS:\n"
"%s"
msgstr ""
"重要なメッセージです:\n"
"%s"

#: ../server/apacheRequest.py:149
#, python-format
msgid ""
"While running '%s': caught\n"
"%s : %s\n"
msgstr ""
"「%s」の実行中: 次をキャッチしました\n"
"%s : %s\n"

#: ../server/apacheRequest.py:606
#, python-format
msgid "Invalid URI %s"
msgstr "無効な URI %s"

#: ../server/rhnChannel.py:1992
#, python-format
msgid ""
"Your account does not have access to any channels matching "
"(release='%(release)s', arch='%(arch)s')%(www_activation)s"
msgstr ""
"ご使用のアカウントには (release='%(release)s', "
"arch='%(arch)s')%(www_activation)s に一致するチャンネルのいずれにもアクセスが"
"ありません"

#: ../server/rhnChannel.py:2002
msgid ""
"\n"
"If you have a registration number, please register with it first at http://"
"www.redhat.com/apps/activate/ and then try again.\n"
"\n"
msgstr ""
"\n"
"登録番号をお持ちの場合は、 まずその番号を http://www.redhat.com/apps/"
"activate/ にて登録してからやり直してください。\n"
"\n"

#: ../server/rhnChannel.py:2012
#, python-format
msgid "Insufficient subscription permissions for release (%s, %s"
msgstr "リリース (%s, %s にはサブスクリプション許可が不足しています"

#. Various messages that can be reused
#.
#. bretm 02/07/2007 -- when we have better old-client documentation, probably
#. will be safe to get rid of all this crap
#: ../server/rhnChannel.py:2276 ../server/rhnChannel.py:2287
#: ../server/rhnChannel.py:2302
msgid "System Registered but Inactive"
msgstr "システムは登録されていますが非アクティブになっています"

#: ../server/rhnChannel.py:2277
#, python-format
msgid ""
"\n"
"Invalid Architecture and OS release combination (%s, %s).\n"
"Your system has been registered, but will not receive updates\n"
"because it is not subscribed to a channel. If you have not yet\n"
"activated your product for service, please visit our website at:\n"
"\n"
"     http://www.redhat.com/apps/activate/\n"
"\n"
"...to activate your product."
msgstr ""
"\n"
"アーキテクチャとオペレーティングシステムのリリースの組み合わせ (%s、 %s)\n"
"が正しくありません。システムは登録されていますが、チャンネルのサブスクリプ"
"ション\n"
"が行なわれていないため更新は行われません。 製品のアクティベーションが\n"
"未実施の場合は、下記の Web サイトにアクセスしてアクティベーションを\n"
"行なってください:\n"
"  \n"
"     http://www.redhat.com/apps/activate/"

#: ../server/rhnChannel.py:2288
#, python-format
msgid ""
"\n"
"Invalid Architecture and OS release combination (%s, %s).\n"
"Your system has been registered, but will not receive updates\n"
"because it could not be subscribed to a base channel.\n"
"Please contact your organization administrator for assistance.\n"
msgstr ""
"\n"
"アーキテクチャとオペレーティングシステムのリリースの組み合わせ (%s、 %s)\n"
"が無効です。 システムは登録されていますが、 ベースチャンネルにサブスクライ"
"ブ\n"
"させることができなかったため更新は行われません。 詳細については組織の管理者"
"に\n"
"お問い合わせください。\n"

#: ../server/rhnChannel.py:2295
#, python-format
msgid ""
"\n"
"  This system has been successfully registered, but is not yet entitled\n"
"  to service.  To entitle this system to service, login to the web site at:\n"
"\n"
"  %(entitlement_url)s\n"
msgstr ""
"\n"
"  このシステムは正常に登録されていますが、 エンタイトルメントがまだ付与されて"
"いません。\n"
"  システムにエンタイトルメントを付与するには次の Web サイトにログインしてくだ"
"さい。\n"
"\n"
"  %(entitlement_url)s\n"

#: ../server/rhnChannel.py:2303
#, python-format
msgid ""
"\n"
"  This system has been successfully registered, but no service entitlements\n"
"  were available.  To entitle this system to service, login to the web site "
"at:\n"
"\n"
"  %(entitlement_url)s\n"
msgstr ""
"\n"
"  このシステムは正常に登録されていますが、 利用できるエンタイトルメントがあり"
"ませんでした。\n"
"  システムにエンタイトルメントを付与するには次の Web サイトにログインしてくだ"
"さい。\n"
"\n"
"  %(entitlement_url)s\n"

#. 0-999: Red Hat client/client-like interaction errors:
#: ../common/rhnException.py:53
msgid "This does not appear to be a valid username."
msgstr "有効なユーザー名ではないようです。"

#: ../common/rhnException.py:54
msgid "Invalid username and password combination."
msgstr "ユーザー名とパスワードの組み合わせが無効です。"

#: ../common/rhnException.py:55
msgid "This login is already taken, or the password is incorrect."
msgstr "このログインは既に使用済か、 またはパスワードが間違っています。"

#: ../common/rhnException.py:56
msgid "Permission denied."
msgstr "パーミッションが拒否されました。"

#: ../common/rhnException.py:57
msgid "Object not found."
msgstr "オブジェクトが見つかりません。"

#: ../common/rhnException.py:58
msgid "Invalid System Digital ID."
msgstr "無効なシステムデジタル ID です。"

#: ../common/rhnException.py:59
msgid "Invalid System Credentials."
msgstr "無効なシステム認証情報です。"

#: ../common/rhnException.py:60
msgid "Could not retrieve user data from database."
msgstr "データベースからユーザーのデータを読み出すことができませんでした。"

#: ../common/rhnException.py:61
msgid "Valid username required."
msgstr "有効なユーザー名が必要です。"

#: ../common/rhnException.py:62
msgid "Valid password required."
msgstr "有効なパスワードが必要です。"

#: ../common/rhnException.py:63
msgid "Minimum username length violation."
msgstr "ユーザー名の最短の長さを違反しています。"

#: ../common/rhnException.py:64
msgid "Minimum password length violation."
msgstr "パスワードの最短の長さを違反しています。"

#: ../common/rhnException.py:65
msgid "The username contains invalid characters."
msgstr "ユーザー名に無効な文字が含まれています。"

#: ../common/rhnException.py:66
msgid "File not found."
msgstr "ファイルが見つかりません。"

#: ../common/rhnException.py:67
msgid "Architecture and OS version combination is not supported."
msgstr ""
"アーキテクチャとオペレーティングシステムのバージョンの組み合わせは対応してい"
"ません。"

#: ../common/rhnException.py:68
msgid "Could not retrieve system data from database."
msgstr "データベースからシステムのデータを読み出すことができませんでした。"

#: ../common/rhnException.py:69
msgid "Invalid arguments passed to function."
msgstr "関数に無効な引数が渡されました。"

#: ../common/rhnException.py:70
msgid "Unable to retrieve requested entry."
msgstr "要求されたエントリを読み出せません。"

#: ../common/rhnException.py:71
msgid "Could not update database entry."
msgstr "データベースのエントリを更新できませんでした。"

#: ../common/rhnException.py:72
msgid "Unsupported server architecture."
msgstr "未対応のサーバーアーキテクチャです。"

#: ../common/rhnException.py:73
#, python-format
msgid ""
"\n"
"     The anonymous server functionality is no longer available.\n"
"\n"
"     Please re-register this system by running mgr_register as root.\n"
"     Please visit https://%(hostname)s/rhn/systems/SystemEntitlements.do\n"
"     or login at https://%(hostname)s, and from the \"Overview\" tab,\n"
"     select \"Subscription Management\" to enable the service for this "
"system.\n"
"     "
msgstr ""
"\n"
"     匿名サーバー機能は利用できなくなっています。\n"
"\n"
"     root になり mgr_register を実行してこのシステムの再登録を行ってくださ"
"い。\n"
"     このシステムに対してサービスを有効にする場合は、 \n"
"     https://%(hostname)s/rhn/systems/SystemEntitlements.do にアクセスする"
"か、\n"
"     https://%(hostname)s でログインしてから \"概要\" タブ内の \"サブスクリプ"
"ション管理\"\n"
"     を選択してください。\n"
"     "

#: ../common/rhnException.py:81
msgid "Record not available in the database."
msgstr "データベースに使用できる記録がありません。"

#: ../common/rhnException.py:82
msgid "Invalid value for entry."
msgstr "エントリには無効な値です。"

#: ../common/rhnException.py:83
#, python-format
msgid ""
"\n"
"     This system does not have a valid entitlement for SUSE Manager.\n"
"     Please visit https://%(hostname)s/rhn/systems/SystemEntitlements.do\n"
"     or login at https://%(hostname)s, and from the \"Overview\" tab,\n"
"     select \"Subscription Management\" to enable the service for this "
"system.\n"
"     "
msgstr ""
"\n"
"     このシステムには SUSE Manager 用の有効なエンタイトルメントがありませ"
"ん。\n"
"     このシステムに対してサービスを有効にする場合は、\n"
"     https://%(hostname)s/rhn/systems/SystemEntitlements.do にアクセスする"
"か、\n"
"     https://%(hostname)s でログインしてから \"概要\" タブ内にある \"サブスク"
"リプション管理\"\n"
"     を選択してください。\n"
"     "

#: ../common/rhnException.py:89
msgid "Channel error"
msgstr "チャンネルエラー"

#: ../common/rhnException.py:90
msgid "Client session token is invalid."
msgstr "クライアントのセッショントークンが無効です。"

#: ../common/rhnException.py:91
msgid "Client session token has expired."
msgstr "クライアントのセッショントークンの有効期限が切れています。"

#: ../common/rhnException.py:92
msgid "You are not authorized to retrieve the requested object."
msgstr "要求されたオブジェクトを読み出す権限が与えられていません。"

#: ../common/rhnException.py:93
msgid "Invalid action"
msgstr "無効な動作"

#: ../common/rhnException.py:94
msgid "You are not allowed to perform administrative tasks on this system."
msgstr "このシステムで管理関連の作業を行う許可がありません。"

#: ../common/rhnException.py:96
msgid "The system is already subscribed to the specified channel."
msgstr "システムは既に指定チャンネルにサブスクライブされています。"

#: ../common/rhnException.py:97
msgid "The system is not currently subscribed to the specified channel."
msgstr "現在、 システムは指定チャンネルにサブスクライブされていません。"

#: ../common/rhnException.py:98
msgid "The specified channel does not exist."
msgstr "指定されたチャンネルが存在していません。"

#: ../common/rhnException.py:99
msgid "Invalid channel version."
msgstr "無効なチャンネルバージョンです。"

#: ../common/rhnException.py:100
msgid ""
"\n"
"     User group membership limits exceeded.\n"
"\n"
"     The current settings for your account do not allow you to add another\n"
"     user account. Please check with the organization administrator for "
"your\n"
"     account if the maximum number of users allowed to subscribe to server "
"needs\n"
"     to be changed.\n"
"     "
msgstr ""
"\n"
"     ユーザーグループのメンバーシップの上限を超えています。\n"
"\n"
"     お使いのアカウントの現在の設定では、これ以上のユーザーアカウントの追加は"
"できません。\n"
"     サーバに対してサブスクリプションを設定できる最大ユーザ数を変更する必要が"
"ある場合は、\n"
"     組織の管理者にご確認ください。\n"
"     "

#: ../common/rhnException.py:108
msgid ""
"\n"
"     System group membership limits exceeded.\n"
"\n"
"     The current settings for your account do not allow you to add another\n"
"     system profile. Please check with the organization administrator for "
"your\n"
"     account for modifying the maximum number of system profiles that can "
"be\n"
"     subscribed to your account.\n"
"     "
msgstr ""
"\n"
"     システムグループのメンバーシップの上限を超えています。\n"
"\n"
"     お使いのアカウントの現在の設定では、これ以上のシステムプロファイルの追加"
"はできません。\n"
"     お使いのアカウントでサブスクリプションを設定できるシステムプロファイル数"
"の最大値を\n"
"     変更する必要がある場合は、組織の管理者にご確認ください。\n"
"     "

#: ../common/rhnException.py:116
msgid ""
"\n"
"     Invalid architecture.\n"
"\n"
"     The architecture of the package is not supported by\n"
"     "
msgstr ""
"\n"
"     アーキテクチャが正しくありません。\n"
"\n"
"     このパッケージのアーキテクチャは対応していません。\n"
"     "

#: ../common/rhnException.py:121
msgid "Invalid RPM header"
msgstr "無効な RPM ヘッダーです"

#: ../common/rhnException.py:122
msgid ""
"\n"
"    This system is already registered as a Salt Minion. If you want to "
"register it as a traditional client\n"
"    please delete it first via the web UI or API and then register it using "
"the traditional tools.\n"
"    "
msgstr ""
"\n"
"    このシステムは既に Salt Minion として登録されています。従来型のクライアン"
"トとして登録したい場合は、\n"
"    Web UI や API でいったん削除を行なったあと、再度従来のツールで登録を行"
"なってください。\n"
"    "

#. For the uploading tools
#: ../common/rhnException.py:127
msgid "Invalid information uploaded to the server"
msgstr "サーバーに無効な情報がアップロードされました"

#: ../common/rhnException.py:128
msgid "Error uploading network interfaces configuration."
msgstr ""
"ネットワークインターフェースの設定をアップロード中にエラーが発生しました。"

#: ../common/rhnException.py:129
msgid ""
"\n"
"     Package Upload Failed due to uniqueness constraint violation.\n"
"     Make sure the package does not have any duplicate dependencies or\n"
"     does not already exists on the server\n"
"     "
msgstr ""
"\n"
"     一意性制約の違反によりパッケージのアップロードが失敗しました。\n"
"     パッケージに重複する依存関係がないこと、 またはこのパッケージが\n"
"     まだサーバーに存在していないことを確認してください。\n"
"     "

#: ../common/rhnException.py:134
msgid ""
"\n"
"     The --force rhnpush option is disabled on this server.\n"
"     Please contact your SUSE Manager administrator for more help.\n"
"     "
msgstr ""
"\n"
"     このサーバーでは --force rhnpush のオプションは無効になっています。\n"
"     詳細については SUSE Manager の管理者にお問い合わせください。\n"
"     "

#. 60-70: token errors
#: ../common/rhnException.py:140
msgid ""
"\n"
"     The activation token specified could not be found on the server.\n"
"     Please retry with a valid key.\n"
"     "
msgstr ""
"\n"
"     指定されたアクティベーショントークンがサーバーに見つかりませんでした。\n"
"     有効なキーでやり直してください。\n"
"     "

#: ../common/rhnException.py:144
msgid "Too many systems registered using this registration token"
msgstr "この登録トークンを使用して登録されたシステムが多すぎます"

#: ../common/rhnException.py:145
msgid "Token contains invalid, obsoleted or insufficient settings"
msgstr ""
"無効な設定、 またはサポートされていないか不適切な設定を含むトークンです"

#: ../common/rhnException.py:146
msgid "Conflicting activation tokens"
msgstr "アクティベーショントークンが競合しています"

#. 70-80: channel subscription errors
#: ../common/rhnException.py:149
msgid ""
"\n"
"     No matching base channel found for your system.\n"
"     "
msgstr ""
"\n"
"     お使いのシステムに該当するベースチャンネルが見つかりませんでした。\n"
"     "

#: ../common/rhnException.py:152
msgid ""
"\n"
"     You do not have subscription permission to the designated channel.\n"
"     Please refer to your organization's channel or organization\n"
"     administrators for further details.\n"
"     "
msgstr ""
"\n"
"     指定チャンネルへのサブスクリプションパーミッションがありません。\n"
"     詳細については組織の管理者またはチャンネル管理者にお問い合わせくださ"
"い。\n"
"     \n"
"     "

#: ../common/rhnException.py:157
msgid "You can not unsubscribe from base channel."
msgstr "ベースチャンネルのサブスクリプションを解除することはできません。"

#: ../common/rhnException.py:158
msgid "SUSE Manager or Proxy channel can not be subscribed."
msgstr ""
"SUSE Manager もしくは Proxy チャンネルはサブスクリプションを設定できません。"

#. 80-90: server group errors
#: ../common/rhnException.py:161
msgid "There was an error while trying to join the system to its groups"
msgstr "システムをそのグループに参加させる途中でエラーが発生しました"

#. 90-100: entitlement errors
#: ../common/rhnException.py:164
msgid "Unable to entitle system"
msgstr "システムにエンタイトルメントを付与できません"

#. 100-109: e-mail and uuid related faults
#: ../common/rhnException.py:167
msgid "Maximum e-mail length violation."
msgstr "Email の最大長を超えています。"

#: ../common/rhnException.py:168
msgid "This system has been previously registered."
msgstr "このシステムは既に登録されています。"

#: ../common/rhnException.py:169
msgid "Invalid username"
msgstr "無効なユーザー名"

#. 140-159 applet errors
#: ../common/rhnException.py:172
msgid "Unable to look up server"
msgstr "サーバーを検出できません"

#. 160-179: OSAD errors
#: ../common/rhnException.py:175
msgid "Required argument is missing"
msgstr "必要な引数がありません"

#. 600-699: RHEL5+ EN errors
#: ../common/rhnException.py:178
msgid "No entitlement information tied to hardware"
msgstr "ハードウェアに関連づけられているエンタイトルメント情報がありません"

#: ../common/rhnException.py:179
msgid "Installation number is not entitling"
msgstr "インストール番号にエンタイトルメントが付与されていません"

#. 700-799: Additional user input verification errors.
#: ../common/rhnException.py:182
msgid "Maximum username length violation"
msgstr "ユーザー名の最大長を超えています"

#: ../common/rhnException.py:183
msgid "Maximum password length violation"
msgstr "パスワードの最大長を超えています"

#: ../common/rhnException.py:184
msgid "This user has read only API access. Action denied."
msgstr ""
"このユーザに対しては読み込み専用の API アクセスのみが提供されています。アクセ"
"スが拒否されました。"

#: ../common/rhnException.py:186
msgid "System Name cannot be less than 1 character"
msgstr "システム名を 1 文字未満にすることはできません"

#. 1000-1999: Proxy specific errors:
#. issued by a Proxy to the client
#: ../common/rhnException.py:190
msgid "SUSE Manager Proxy error."
msgstr "SUSE Manager Proxy のエラーです。"

#: ../common/rhnException.py:191
msgid "SUSE Manager Proxy unable to login."
msgstr "SUSE Manager Proxy によるログインができません。"

#. issued by a SUSE Manager Server/Satellite to the proxy
#: ../common/rhnException.py:193
msgid ""
"\n"
"     SUSE Manager Proxy system ID does not match a Spacewalk Proxy Server\n"
"     in the database.\n"
"     "
msgstr ""
"\n"
"     SUSE Manager Proxy のシステム ID と、データベース内の Spacewalk Proxy "
"Server\n"
"     の情報が合致しません。\n"
"     "

#: ../common/rhnException.py:197
msgid "SUSE Manager Proxy session token is invalid."
msgstr "SUSE Manager Proxy セッショントークンが正しくありません。"

#: ../common/rhnException.py:198
msgid "SUSE Manager Proxy session token has expired."
msgstr "SUSE Manager Proxy セッショントークンの期限が切れています。"

#. 2000-2999: Red Hat Satellite specific errors:
#: ../common/rhnException.py:202
msgid ""
"\n"
"      user creation is not allowed via mgr_register;\n"
"     please contact your sysadmin to have your account created.\n"
"     "
msgstr ""
"\n"
"      mgr_register 経由でのユーザ作成は許可されていません;\n"
"     システム管理者にアカウントの作成を依頼してください。\n"
"     "

#: ../common/rhnException.py:206
msgid ""
"\n"
"     This SUSE Manager server is not allowed to use Inter Server Sync on "
"this server\n"
"     "
msgstr ""
"\n"
"     この SUSE Manager サーバーでは、このサーバでの Inter Server Sync の使用"
"が許可されていません\n"
"     "

#: ../common/rhnException.py:209
msgid ""
"\n"
"     Inter Server Sync is disabled on this SUSE Manager Server.\n"
"     "
msgstr ""
"\n"
"     Inter Server Sync は、この SUSE Manager サーバでは無効化されています。\n"
"     "

#. 3000-3999: XML dumper errors:
#: ../common/rhnException.py:214
msgid "Invalid datatype passed"
msgstr "無効なデータタイプが渡されています"

#: ../common/rhnException.py:215
msgid "Unable to retrieve channel"
msgstr "チャンネルが読み出せません"

#: ../common/rhnException.py:216
msgid "Unable to retrieve package"
msgstr "パッケージが読み出せません"

#: ../common/rhnException.py:217
msgid "Unable to retrieve erratum"
msgstr "エラータが読み出せません"

#: ../common/rhnException.py:218
msgid "File is missing"
msgstr "ファイルがありません"

#: ../common/rhnException.py:219
msgid "Function retrieval error"
msgstr "関数読み出しのエラーです"

#: ../common/rhnException.py:220
msgid "Function execution error"
msgstr "関数実行エラーです"

#: ../common/rhnException.py:221
msgid "Missing version string"
msgstr "バージョン文字列がありません"

#: ../common/rhnException.py:222
msgid "Invalid version string"
msgstr "無効なバージョン文字列です"

#: ../common/rhnException.py:223
msgid "Mismatching versions"
msgstr "バージョンが一致しません"

#: ../common/rhnException.py:224
msgid "Invalid channel version"
msgstr "無効なチャンネルバージョンです"

#: ../common/rhnException.py:225
msgid "No comps file for channel"
msgstr "チャンネル用の comps ファイルがありません"

#: ../common/rhnException.py:226
msgid "Unable to retrieve comps file"
msgstr "comps ファイルが読み出せません"

#. 4000 - 4999: config management errors
#: ../common/rhnException.py:229
msgid "Configuration action missing"
msgstr "設定動作がありません"

#: ../common/rhnException.py:230
msgid "File too large"
msgstr "ファイルが長すぎます"

#: ../common/rhnException.py:231
msgid "File contains binary data"
msgstr "ファイルにバイナリデータが含まれています"

#: ../common/rhnException.py:232
msgid "Configuration channel is not empty"
msgstr "設定チャンネルが空になっていません"

#: ../common/rhnException.py:233
msgid "Permission error"
msgstr "パーミッションエラーです"

#: ../common/rhnException.py:234
msgid "Content missing for configuration file"
msgstr "設定ファイルの内容がありません"

#: ../common/rhnException.py:235
msgid "Template delimiters not specified"
msgstr "テンプレートの区切り文字が指定されていません"

#: ../common/rhnException.py:236
msgid "Configuration channel does not exist"
msgstr "設定チャンネルが存在していません"

#: ../common/rhnException.py:237
msgid "Configuration channel already exists"
msgstr "設定チャンネルは既に存在しています"

#: ../common/rhnException.py:238
msgid "File missing from configuration channel"
msgstr "設定チャンネルからのファイルがありません"

#: ../common/rhnException.py:239
msgid "Different revision of this file is uploaded"
msgstr "このファイルの別の改訂版がアップロードされています"

#: ../common/rhnException.py:240
msgid "File already uploaded to configuration channel"
msgstr "ファイルは既に設定チャンネルにアップロードされています"

#: ../common/rhnException.py:241
msgid "File size exceeds remaining quota space"
msgstr "ファイルサイズが残りの上限領域を超えています"

#: ../common/rhnException.py:242
msgid "Full path of file must be specified"
msgstr "ファイルの完全パスを指定してください"

#: ../common/rhnException.py:243
msgid "Invalid revision number"
msgstr "無効な改訂版番号です"

#: ../common/rhnException.py:244
msgid "Cannot compare files of different file type"
msgstr "タイプが異なるファイル同士は比較できません"

#. 5000 - 5999: client content uploading errors
#. 5000 - 5099: crash reporting errors
#: ../common/rhnException.py:248
msgid "Crash information is invalid or incomplete"
msgstr "クラッシュ情報が正しくないか、不完全です"

#: ../common/rhnException.py:249
msgid "Crash file information is invalid or incomplete"
msgstr "クラッシュファイルの情報が正しくないか、不完全です"

#: ../common/rhnException.py:250
msgid "Error composing crash directory path"
msgstr "クラッシュディレクトリパスの生成時にエラー"

#: ../common/rhnException.py:251
msgid "Error composing crash file path"
msgstr "クラッシュファイルパスの生成時にエラー"

#: ../common/rhnException.py:252 ../common/rhnException.py:259
msgid "Invalid content encoding"
msgstr "コンテンツエンコーディングが正しくありません"

#: ../common/rhnException.py:253
msgid "Invalid crash name"
msgstr "クラッシュ名が正しくありません"

#: ../common/rhnException.py:254
msgid "Crash reporting is disabled for this organization"
msgstr "この組織に対してはクラッシュ報告機能が無効化されています"

#. 5100 - 5199: scap results reporting error
#: ../common/rhnException.py:256
msgid "SCAP results file transfer is invalid or incomplete"
msgstr "SCAP results のファイル転送が正しくないか、不完全です"

#: ../common/rhnException.py:257
msgid "Error composing directory path for detailed SCAP results"
msgstr "詳細な SCAP results に対するディレクトリパスの生成時にエラー"

#: ../common/rhnException.py:258
msgid "Error composing file path for detailed SCAP results"
msgstr "詳細な SCAP results に対するファイルパスの生成時にエラー"

#: ../common/rhnException.py:306
msgid ""
"\n"
"     An error has occurred while processing your request. If this problem\n"
"     persists please enter a bug report at scc.suse.com.\n"
"     If you choose to submit the bug report, please be sure to include\n"
"     details of what you were trying to do when this error occurred and\n"
"     details on how to reproduce this problem.\n"
msgstr ""
"\n"
"     要求の処理中にエラーが発生しました。 問題が解決しない場合は、\n"
"     scc.suse.com にてバグ報告を提出してください。\n"
"     バグ報告を行なう場合は、 エラーが起きたときに何を行なおうとしていたの"
"か、\n"
"     また問題を再現する場合の手順などを詳しく記入していただけるよう\n"
"     お願いします。\n"

#: ../common/rhnException.py:358
#, python-format
msgid ""
"Error Message:\n"
"    %s\n"
msgstr ""
"エラーメッセージ:\n"
"    %s\n"

#: ../common/rhnException.py:360
#, python-format
msgid "Error Class Code: %s\n"
msgstr "エラークラスコード: %s\n"

#: ../common/rhnException.py:363
#, python-format
msgid "Error Class Info: %s\n"
msgstr "エラークラス情報: %s\n"

#: ../common/rhnException.py:365
#, python-format
msgid "Explanation: %s"
msgstr "説明: %s"

#: ../common/rhnTB.py:205
#, python-format
msgid "ERROR: %s %s: %s"
msgstr "エラー: %s %s: %s"

#: ../common/rhnTB.py:207
#, python-format
msgid "TRACEBACK: %s"
msgstr "トレースバック: %s"

#: ../satellite_tools/disk_dumper/iss.py:1294
#: ../satellite_tools/disk_dumper/iss.py:1298
#, python-format
msgid "format of %s should be at least YYYYMMDD.\n"
msgstr "%s の書式は少なくとも YYYYMMDD であるべきです。\n"

#: ../satellite_tools/messages.py:26
#, python-format
msgid ""
"\n"
"ERROR: executing step %s. Error is:\n"
"%s\n"
msgstr ""
"\n"
"エラー: ステップ %s の実行時にエラー:\n"
"%s\n"

#: ../satellite_tools/messages.py:31
#, python-format
msgid ""
"\n"
"ERROR: there was a problem accessing the channel data from your temporary\n"
"       repository. Did you migrate all of the data from the channel ISOs\n"
"       do this directory? If so, please recheck the channels ISOs, ensure\n"
"       that you have them all, and then iteratively remount and repopulate\n"
"       the temporary repository (%s).\n"
msgstr ""
"\n"
"エラー: 一時リポジトリーからチャンネルデータにアクセスする際に問題がありまし"
"た。\n"
"       このディレクトリに対して、チャンネル ISO からの全てのデータを移行して"
"ありますか？\n"
"       チャンネル ISO の内容が全て移行されていることを確認して再度マウントを"
"行ない、\n"
"       一時リポジトリー (%s) 内に再投入してください。\n"

#: ../satellite_tools/messages.py:39
#, python-format
msgid ""
"\n"
"ERROR: there was a problem synchronizing the information.\n"
"       Error message: %s\n"
msgstr ""
"\n"
"エラー: 情報を同期する際に問題がありました。\n"
"       エラーメッセージ: %s\n"

#: ../satellite_tools/messages.py:44
#, python-format
msgid ""
"\n"
"ERROR: There was a problem communicating with the ISS Master.\n"
"       Depending on the specific error details, please review your "
"configuration,\n"
"       basic network connectivity, and/or name resolution, and try again.\n"
"       Error message: %s\n"
msgstr ""
"\n"
"エラー: ISS Master と通信する際に問題がありました。\n"
"       エラーの詳細にもよりますが、設定やネットワークの接続、名前解決などが正"
"しく動作\n"
"       することをご確認のうえ、やり直してください。\n"
"       エラーメッセージ: %s\n"

#: ../satellite_tools/messages.py:51
#, python-format
msgid ""
"\n"
"ERROR: There was a problem communicating with the ISS Master.\n"
"       If the master satellite is older than v5.3, it does not have ISS "
"capability.\n"
"       Otherwise, depending on the specific error details, please review "
"your\n"
"       configuration, basic network connectivity, and/or name resolution, "
"and try again.\n"
"       Error message: %s\n"
msgstr ""
"\n"
"エラー: ISS Master との通信する際にエラーがありました。\n"
"       マスター Satellite がバージョン 5.3 よりも古い場合、 ISS の機能は提供"
"されていません。\n"
"       マスター Satellite がバージョン 5.3 もしくはそれ以降の場合は、エラーの"
"詳細にもよりますが、\n"
"       設定やネットワークの接続、名前解決などが正しく動作することをご確認のう"
"え、やり直してください。\n"
"       エラーメッセージ: %s\n"

#: ../satellite_tools/messages.py:59
#, python-format
msgid ""
"\n"
"ERROR: a child-channel cannot be synced without its parent being synced as\n"
"       well. A parent needs to be either (a) previously synced or (b) "
"synced\n"
"       in tandem with the desired child-channel. Missing parents for this\n"
"       transaction:\n"
"       %s\n"
msgstr ""
"\n"
"エラー: 子チャンネルを同期するにあたっては、親チャンネルも同期する必要があり"
"ます。\n"
"       親チャンネルは以前に同期されているか、もしくは子チャンネルと並行して同"
"期させる\n"
"       必要があります。このトランザクションに対する親が見つかりません:\n"
"       %s\n"

#: ../satellite_tools/messages.py:67
#, python-format
msgid ""
"\n"
"ERROR: you are not entitled to sync a channel in this set of channels.\n"
"Please contact your SUSE Manager contact\n"
"%s"
msgstr ""
"\n"
"エラー: このチャンネルセット内でチャンネルを同期するためのエンタイトルメント"
"がありません。\n"
"SUSE Manager に連絡を行なってください\n"
"%s"

#: ../satellite_tools/messages.py:72
#, python-format
msgid "  ERROR: not enough free space (%s KB) on device."
msgstr "  エラー: デバイスに十分な空き容量 (%s KB) がありません。"

#: ../satellite_tools/messages.py:74
#, python-format
msgid "    %3d/%s Fetch successful: %s (%s bytes)"
msgstr "    %3d/%s フェッチ成功: %s (%s バイト)"

#: ../satellite_tools/messages.py:75
#, python-format
msgid "    Extinct package:  %s"
msgstr "    廃止されたパッケージ:  %s"

#: ../satellite_tools/messages.py:76
#, python-format
msgid "   Total size: %s"
msgstr "   合計サイズ: %s"

#: ../satellite_tools/messages.py:77
#, python-format
msgid "      Downloaded %s of %s. Estimated remaining time: %s"
msgstr "      %s / %s をダウンロード済みです。予測される残り時間: %s"

#: ../satellite_tools/messages.py:78
#, python-format
msgid "    Fetch unsuccessful: %s"
msgstr "    フェッチ未成功: %s"

#: ../satellite_tools/messages.py:79
#, python-format
msgid "   RPM fetch summary: %s"
msgstr "   RPM フェッチ概要: %s"

#: ../satellite_tools/messages.py:80
#, python-format
msgid "       success: %d"
msgstr "       成功: %d"

#: ../satellite_tools/messages.py:81
#, python-format
msgid "       failed:  %d"
msgstr "       失敗:  %d"

#: ../satellite_tools/messages.py:82
#, python-format
msgid "       extinct: %d"
msgstr "       消滅: %d"

#: ../satellite_tools/messages.py:84
#, python-format
msgid "   Retrieving / parsing *relevant* package metadata: %s (%s)"
msgstr "   *関連する* パッケージのメタデータを取得／処理しています: %s (%s)"

#: ../satellite_tools/messages.py:85
#, python-format
msgid "   Retrieving / parsing errata data: %s (%s)"
msgstr "   エラータのデータを取得／処理しています: %s (%s)"

#: ../satellite_tools/messages.py:86
#, python-format
msgid "   Retrieving / parsing kickstart data: %s (%s)"
msgstr "   キックスタートのデータを取得／処理しています: %s (%s)"

#: ../satellite_tools/messages.py:87
#, python-format
msgid "   Retrieving / parsing kickstart tree files: %s (%s)"
msgstr "   キックスタートのツリーファイルを取得／処理しています: %s (%s)"

#: ../satellite_tools/messages.py:88
#, python-format
msgid "   Importing *relevant* package metadata: %s (%s)"
msgstr "   *関連する* パッケージのメタデータを取り込んでいます: %s (%s)"

#: ../satellite_tools/messages.py:89
msgid "   * WARNING: this may be a slow process."
msgstr "   * 警告: この処理には時間がかかるかもしれません。"

#: ../satellite_tools/messages.py:90
msgid "Linking packages to channels"
msgstr "チャンネルに対してパッケージのリンクを作成しています"

#: ../satellite_tools/messages.py:91
#, python-format
msgid "   Importing *relevant* errata: %s (%s)"
msgstr "   *関連する* エラータを取り込んでいます: %s (%s)"

#: ../satellite_tools/messages.py:92
msgid "   No new kickstartable tree to import"
msgstr "   取り込むべき新しいキックスタート可能なツリーはありません"

#: ../satellite_tools/messages.py:93
#, python-format
msgid "Importing kickstartable trees (%d)"
msgstr "キックスタート可能なツリーを取り込んでいます (%d)"

#: ../satellite_tools/messages.py:94
#, python-format
msgid "Imported kickstartable trees (%d)"
msgstr "キックスタート可能なツリーを取り込みました (%d)"

#: ../satellite_tools/rhn_satellite_activate.py:198
#, python-format
msgid ""
"\"%s\" (specified in commandline)\n"
"could not be opened and read:\n"
"%s"
msgstr ""
"\"%s\" (コマンドライン内で指定されています)\n"
"を開いて読み込むことができません:\n"
"%s"

#: ../satellite_tools/rhn_satellite_activate.py:205
#, python-format
msgid ""
"\"%s\" could not be opened\n"
"and/or written to:\n"
"%s"
msgstr ""
"\"%s\" を開いたり書き込んだりする\n"
"ことができません:\n"
"%s"

#: ../satellite_tools/reposync.py:111 ../satellite_tools/satsync.py:439
msgid "+++ sending log as an email +++"
msgstr "+++ 電子メールでログを送信 +++"

#: ../satellite_tools/reposync.py:114
#, python-format
msgid "%s sync. report from %s"
msgstr "%s 同期。 %s からのレポート"

#: ../satellite_tools/reposync.py:124 ../satellite_tools/satsync.py:449
msgid "+++ email requested, but there is nothing to send +++"
msgstr "+++ 電子メールの要求がありましたが、送信すべき内容がありません +++"

#: ../satellite_tools/satsync.py:258
#, python-format
msgid "No handler for step %s"
msgstr "ステップ %s に対するハンドラがありません"

#. Try one more time - this time it should be faster since
#. everything should be cached
#: ../satellite_tools/satsync.py:270
msgid "Environment changed, trying again..."
msgstr "環境が変更されました。再試行しています..."

#: ../satellite_tools/satsync.py:277
msgid "ERROR: Encountered IntegrityError: \n"
msgstr "エラー: IntegrityError に遭遇しました: \n"

#: ../satellite_tools/satsync.py:285
msgid "Repeated failures"
msgstr "繰り返しの失敗"

#: ../satellite_tools/satsync.py:290
#, python-format
msgid ""
"    Import complete:\n"
"        Begin time: %s\n"
"        End time:   %s\n"
"        Elapsed:    %s\n"
"          "
msgstr ""
"    取り込みが完了しました:\n"
"        開始時刻: %s\n"
"        終了時刻: %s\n"
"        経過時間: %s\n"
"          "

#: ../satellite_tools/satsync.py:311
msgid "hours"
msgstr "時間"

#: ../satellite_tools/satsync.py:311
msgid "minutes"
msgstr "分"

#: ../satellite_tools/satsync.py:311
msgid "seconds"
msgstr "秒"

#: ../satellite_tools/satsync.py:357
msgid ""
"ERROR: The dump is missing package data, use --no-rpms to skip this step or "
"fix the content to include package data."
msgstr ""
"エラー: ダンプにはパッケージデータがありません。 --no-rpms を指定してこのス"
"テップを飛ばすか、パッケージデータが含まれるように内容を修正してください。"

#. the orgs() method doesn't exist; that's fine we just
#. won't sync the orgs
#: ../satellite_tools/satsync.py:404
msgid "The SUSE Manager master does not support syncing orgs data."
msgstr "SUSE Manager マスターは組織データの同期をサポートしていません。"

#: ../satellite_tools/satsync.py:404
msgid "Skipping..."
msgstr "飛ばしています..."

#: ../satellite_tools/satsync.py:442
#, python-format
msgid "SUSE Manager Inter Server sync. report from %s"
msgstr "SUSE Manager サーバ間同期です。 %s からのレポート"

#: ../satellite_tools/satsync.py:521
msgid " - file-system synchronization"
msgstr " - ファイルシステムの同期"

#: ../satellite_tools/satsync.py:533 ../satellite_tools/satsync.py:541
msgid " - live synchronization"
msgstr " - ライブ同期"

#: ../satellite_tools/satsync.py:534
#, python-brace-format
msgid ""
"ERROR: Live content synchronizing with RHN Classic Hosted is no longer "
"supported.\n"
"Please use the cdn-sync command instead unless you are attempting to sync "
"from another {PRODUCT_NAME} via Inter-Server-Sync (ISS), or from local "
"content on disk via Channel Dump ISOs."
msgstr ""
"エラー: RHN Classic Hosted を利用したライブコンテンツの同期は、もはやサポート"
"されていません。\n"
"サーバ間同期 (ISS) を介して他の {PRODUCT_NAME} から同期を行なっている場合や、"
"チャンネルダンプ ISO を利用してディスク内のローカルコンテンツから同期を行なっ"
"ている場合を除き、代わりに cdn-sync コマンドを使用してください。"

#: ../satellite_tools/satsync.py:542
#, python-format
msgid "   url: %s"
msgstr "   URL: %s"

#: ../satellite_tools/satsync.py:543
#, python-format
msgid "   debug/output level: %s"
msgstr "   デバッグ／出力レベル: %s"

#: ../satellite_tools/satsync.py:553
msgid "ERROR: this server must be registered with SUSE Manager."
msgstr "エラー: このサーバを SUSE Manager で登録しなければなりません。"

#: ../satellite_tools/satsync.py:575
#, python-format
msgid "Retrieving / parsing %s data"
msgstr "%s のデータを取得／処理しています"

#: ../satellite_tools/satsync.py:585 ../satellite_tools/satsync.py:600
msgid "*** SYSTEM INTERRUPT CALLED ***"
msgstr "*** システム割り込みが呼び出されました ***"

#: ../satellite_tools/satsync.py:593
msgid "ERROR: fatal parser exception occurred "
msgstr "エラー: 致命的な処理例外が発生しました "

#: ../satellite_tools/satsync.py:594
#, python-format
msgid "(line: %s, col: %s msg: %s)"
msgstr "(行: %s, 列: %s メッセージ: %s)"

#: ../satellite_tools/satsync.py:598
#, python-format
msgid "ERROR: parser exception occurred: %s"
msgstr "エラー: 処理例外が発生しました: %s"

#: ../satellite_tools/satsync.py:603
msgid "ERROR: exception (during parse) occurred: "
msgstr "エラー: 例外 (処理時) が発生しました: "

#: ../satellite_tools/satsync.py:604
#, python-format
msgid ""
"   Encountered some errors with %s data (see logs (%s) for more information)"
msgstr ""
"   %s データでいくつかのエラーに遭遇しました (詳しくはログ (%s) をお読みくだ"
"さい)"

#: ../satellite_tools/satsync.py:606
#, python-format
msgid "   Encountered some errors with %s data:"
msgstr "   %s データでいくつかのエラーに遭遇しました:"

#: ../satellite_tools/satsync.py:607
#, python-format
msgid "   ------- %s PARSE/IMPORT ERROR -------"
msgstr "   ------- %s 処理／取り込みエラー -------"

#: ../satellite_tools/satsync.py:609
msgid "   ---------------------------------------"
msgstr "   ---------------------------------------"

#: ../satellite_tools/satsync.py:612
#, python-format
msgid "%s data complete"
msgstr "%s データ完了"

#: ../satellite_tools/satsync.py:665
msgid "Retrieving / parsing channel data"
msgstr "チャンネルデータの取得／処理を行なっています"

#: ../satellite_tools/satsync.py:718
msgid "Channel data complete"
msgstr "チャンネルデータ完了"

#: ../satellite_tools/satsync.py:736
#, python-format
msgid "%10s import from %s"
msgstr "%10s %s から取り込み"

#: ../satellite_tools/satsync.py:739
#, python-format
msgid "%10s import from %s - %s"
msgstr "%10s %s - %s から取り込み"

#: ../satellite_tools/satsync.py:743
#, python-format
msgid "%10s"
msgstr "%10s"

#: ../satellite_tools/satsync.py:750
msgid "p"
msgstr "p"

#: ../satellite_tools/satsync.py:752
msgid "."
msgstr "."

#: ../satellite_tools/satsync.py:758
msgid "   p = previously imported/synced channel"
msgstr "   p = 以前に取り込み／同期したチャンネル"

#: ../satellite_tools/satsync.py:759
msgid "   . = channel not yet imported/synced"
msgstr "   . = まだ取り込み／同期していないチャンネル"

#: ../satellite_tools/satsync.py:765
msgid "   e = channel no longer supported (end-of-service)"
msgstr "   e = サポート対象外のチャンネル (サービス終了済み)"

#: ../satellite_tools/satsync.py:767
msgid "   ? = channel label invalid --- typo?"
msgstr "   ? = チャンネルラベルが正しくないもの (指定ミス？)"

#: ../satellite_tools/satsync.py:771
#, python-format
msgid "   %s:"
msgstr "   %s:"

#: ../satellite_tools/satsync.py:772
#, python-format
msgid "      %s %-40s %4s %s"
msgstr "      %s %-40s %4s %s"

#: ../satellite_tools/satsync.py:773
msgid "base-channels"
msgstr "ベースチャンネル"

#: ../satellite_tools/satsync.py:786 ../satellite_tools/satsync.py:1603
msgid "NONE RELEVANT"
msgstr "関係なし"

#: ../satellite_tools/satsync.py:808
msgid "end-of-service"
msgstr "サービス終了"

#: ../satellite_tools/satsync.py:809
msgid "e"
msgstr "e"

#: ../satellite_tools/satsync.py:815
msgid "   typos:"
msgstr "   誤記:"

#: ../satellite_tools/satsync.py:816
msgid "?"
msgstr "?"

#: ../satellite_tools/satsync.py:831
#, python-format
msgid "XXX: imported channels: %s"
msgstr "XXX: 取り込んだチャンネル: %s"

#: ../satellite_tools/satsync.py:832
#, python-format
msgid "XXX:   cached channels: %s"
msgstr "XXX:   キャッシュしたチャンネル: %s"

#: ../satellite_tools/satsync.py:837
msgid "XXX: list channels called"
msgstr "XXX: 呼び出したチャンネルの一覧"

#: ../satellite_tools/satsync.py:855
msgid "ERROR: these channels either do not exist or are not available:"
msgstr "エラー: これらのチャンネルは存在していないか、利用ができません:"

#: ../satellite_tools/satsync.py:859
#, python-format
msgid "       (to see a list of channel labels: %s --list-channels)"
msgstr "       (チャンネルラベルの一覧を表示するには: %s --list-channels)"

#: ../satellite_tools/satsync.py:904
#, python-format
msgid "   Retrieving / parsing short package metadata: %s (%s)"
msgstr "   短いパッケージのメタデータを取得／処理しています: %s (%s)"

#: ../satellite_tools/satsync.py:965
#, python-format
msgid "Diffing package metadata (what's missing locally?): %s"
msgstr ""
"パッケージのメタデータの差分を抽出しています (ローカル側に何が無いのかを調べ"
"ています): %s"

#: ../satellite_tools/satsync.py:971 ../satellite_tools/satsync.py:1254
msgid "Diffing:    "
msgstr "差分を抽出しています:    "

#: ../satellite_tools/satsync.py:988
msgid "ERROR: incremental dump skipped"
msgstr "エラー: 増分ダンプを飛ばしました"

#: ../satellite_tools/satsync.py:1079
msgid "Downloading rpm packages"
msgstr "rpm パッケージをダウンロードしています"

#: ../satellite_tools/satsync.py:1084
#, python-format
msgid "   Fetching any missing RPMs: %s (%s)"
msgstr "   存在していない RPM をフェッチしています: %s (%s)"

#: ../satellite_tools/satsync.py:1085 ../satellite_tools/satsync.py:1153
msgid "NONE MISSING"
msgstr "存在しないものはありません"

#: ../satellite_tools/satsync.py:1094
msgid "Processing rpm packages complete"
msgstr "rpm パッケージの処理が完了しました"

#: ../satellite_tools/satsync.py:1121
msgid "Downloading package metadata"
msgstr "パッケージのメタデータをダウンロードしています"

#: ../satellite_tools/satsync.py:1146
msgid "Downloading srpm packages"
msgstr "srpm パッケージをダウンロードしています"

#: ../satellite_tools/satsync.py:1152
#, python-format
msgid "   Fetching any missing SRPMs: %s (%s)"
msgstr "   存在していない SRPM をフェッチしています: %s (%s)"

#: ../satellite_tools/satsync.py:1249
#, python-format
msgid "Diffing source package metadata (what's missing locally?): %s"
msgstr ""
"ソースパッケージのメタデータの差分を抽出しています (ローカル側に何が無いのか"
"を調べています): %s"

#: ../satellite_tools/satsync.py:1260
msgid "Downloading source package metadata"
msgstr "ソースパッケージのメタデータをダウンロードしています"

#: ../satellite_tools/satsync.py:1338 ../satellite_tools/satsync.py:2027
#, python-format
msgid "Unable to save file %s: %s"
msgstr "ファイル %s を保存できません: %s"

#. for
#. Retried a number of times and it still failed; log the
#. file as being failed and move on
#: ../satellite_tools/satsync.py:1345
#, python-format
msgid "Failed to fetch file %s"
msgstr "ファイル %s のフェッチが失敗しました"

#: ../satellite_tools/satsync.py:1350
msgid "Downloading kickstartable trees metadata"
msgstr "キックスタート可能なツリーのメタデータをダウンロードしています"

#: ../satellite_tools/satsync.py:1365
msgid "Downloading kickstartable trees files"
msgstr "キックスタート可能なツリーファイルをダウンロードしています"

#: ../satellite_tools/satsync.py:1504
#, python-format
msgid "Grabbing all patches for channel %s"
msgstr "チャンネル %s に対する全てのパッチをつかんでいます"

#: ../satellite_tools/satsync.py:1554
msgid "Downloading patch data"
msgstr "パッチデータをダウンロードしています"

#: ../satellite_tools/satsync.py:1556
msgid "Forcing download of all patch data for requested channels."
msgstr ""
"要求したチャンネルに対する全てのパッチデータを強制ダウンロードしています。"

#: ../satellite_tools/satsync.py:1571
msgid "Downloading patch data complete"
msgstr "パッチデータのダウンロードが完了しました"

#: ../satellite_tools/satsync.py:1576 ../satellite_tools/satsync.py:1597
msgid "Downloading:"
msgstr "ダウンロードしています:"

#: ../satellite_tools/satsync.py:1579
msgid " - complete"
msgstr " - 完了"

#: ../satellite_tools/satsync.py:1624
msgid "Importing source package metadata"
msgstr "ソースパッケージのメタデータを取り込んでいます"

#: ../satellite_tools/satsync.py:1627
msgid "Importing package metadata"
msgstr "パッケージのメタデータを取り込んでいます"

#: ../satellite_tools/satsync.py:1635
msgid "Importing:  "
msgstr "取り込んでいます:  "

#. not in the cache
#: ../satellite_tools/satsync.py:1703
msgid ""
"Package Not Found in Cache, Clear the Cache "
"to                                  Regenerate it."
msgstr ""
"キャッシュ内にはパッケージが見つかりません。キャッシュを再生成するにはクリア"
"してください。"

#: ../satellite_tools/satsync.py:1709
msgid "Importing channel patches"
msgstr "チャンネルパッチを取り込んでいます"

#: ../satellite_tools/satsync.py:1714
#, python-format
msgid "Importing %s patches for channel %s."
msgstr "%s 個のパッチをチャンネル %s に対して取り込んでいます。"

#. Incomplete configuration
#: ../satellite_tools/satsync.py:2113
msgid "ERROR: server.mount_point not set in the configuration file"
msgstr "エラー: 設定ファイル内で server.mount_point が設定されていません"

#: ../satellite_tools/satsync.py:2117
#, python-format
msgid "ERROR: server.mount_point %s do not exist"
msgstr "エラー: server.mount_point %s が存在しません"

#: ../satellite_tools/satsync.py:2122
#, python-format
msgid "ERROR: path under server.mount_point (%s)  do not exist"
msgstr "エラー: server.mount_point (%s) 以下のパスが存在していません"

#: ../satellite_tools/satsync.py:2199
#, python-format
msgid "Commandline: %s"
msgstr "コマンドライン: %s"

#: ../satellite_tools/satsync.py:2202
#, python-format
msgid ""
"DEBUG ONLY: max. batch-size for XML/database-import processing (1..%s).\"man "
"satellite-sync\" for more information."
msgstr ""
"デバッグのみ: XML／データベース取り込みに対する最大バッチサイズ (1..%s) 。詳"
"しくは \"man satellite-sync\" をお読みください。"

#: ../satellite_tools/satsync.py:2205
msgid "alternative SSL CA Cert (fullpath to cert file)"
msgstr "代替 SSL CA 証明書 (証明書ファイルに対するフルパス)"

#: ../satellite_tools/satsync.py:2207
msgid "process data for this channel only"
msgstr "このチャンネルに対してのみデータを処理"

#: ../satellite_tools/satsync.py:2209
msgid ""
"disk dump will be considered to be a full export; see \"man satellite-sync\" "
"for more information."
msgstr ""
"ディスクダンプは完全エクスポートと考えられます。詳しくは \"man satellite-sync"
"\" をお読みください。"

#: ../satellite_tools/satsync.py:2212
msgid "existing custom channels will also be synced (unless -c is used)"
msgstr "既存の独自チャンネルについても同期が行なわれます (-c を指定しない限り)"

#: ../satellite_tools/satsync.py:2214
#, python-format
msgid ""
"override debug level set in /etc/rhn/rhn.conf (which is currently set at %s)."
msgstr ""
"/etc/rhn/rhn.conf  内でデバッグレベルを上書き (現在 %s に設定されています) 。"

#: ../satellite_tools/satsync.py:2216
#, python-format
msgid "requested version of XML dump (default: %s)"
msgstr "XML ダンプの要求バージョン (既定値: %s)"

#: ../satellite_tools/satsync.py:2218
msgid "e-mail a report of what was synced/imported"
msgstr "同期および取り込んだもののレポートを電子メール送信"

#: ../satellite_tools/satsync.py:2220
msgid "forcibly process all (not a diff of) patch metadata"
msgstr "全てのパッチのメタデータを (差分処理ではなく) 強制処理"

#: ../satellite_tools/satsync.py:2222
msgid "Do not use an http proxy under any circumstances."
msgstr "どのような状況下でも http プロキシを使用しません。"

#: ../satellite_tools/satsync.py:2224
msgid "alternative http proxy (hostname:port)"
msgstr "代替 http プロキシ (ホスト名:ポート)"

#: ../satellite_tools/satsync.py:2226
msgid "alternative http proxy username"
msgstr "代替 http プロキシのユーザ名"

#: ../satellite_tools/satsync.py:2228
msgid "alternative http proxy password"
msgstr "代替 http プロキシのパスワード"

#: ../satellite_tools/satsync.py:2230
msgid "parent SUSE Manager to import content from"
msgstr "コンテンツのインポート元となる親 SUSE Manager"

#: ../satellite_tools/satsync.py:2232
msgid "list all available channels and exit"
msgstr "利用可能な全てのチャンネルを一覧表示して終了"

#: ../satellite_tools/satsync.py:2234
msgid "help on all error codes mgr-inter-sync returns"
msgstr "mgr-inter-sync が返す全てのエラーコードに対するヘルプ"

#: ../satellite_tools/satsync.py:2236
msgid "source mount point for import - disk update only"
msgstr "取り込み元となるマウントポイント - ディスク更新の場合のみ"

#: ../satellite_tools/satsync.py:2238
msgid "do not process patch data"
msgstr "パッチデータを処理しない"

#: ../satellite_tools/satsync.py:2240
msgid "do not process kickstart data (provisioning only)"
msgstr "キックスタートデータを処理しない (プロビジョニングのみ)"

#: ../satellite_tools/satsync.py:2242
msgid "do not process full package metadata"
msgstr "完全パッケージメタデータを処理しない"

#: ../satellite_tools/satsync.py:2244
msgid "do not download, or process any RPMs"
msgstr "RPM のダウンロードと処理を行なわない"

#: ../satellite_tools/satsync.py:2246
msgid "turn off SSL (not recommended)"
msgstr "SSL を無効化する (非推奨)"

#: ../satellite_tools/satsync.py:2248
msgid "org to which the sync imports data. defaults to the admin account"
msgstr "sync のデータの取り込み先となる組織。既定値は管理者アカウント"

#: ../satellite_tools/satsync.py:2250
msgid "print the configuration and exit"
msgstr "設定を印刷して終了"

#: ../satellite_tools/satsync.py:2252
msgid "alternative server with which to connect (hostname)"
msgstr "接続先の代替サーバ (ホスト名)"

#: ../satellite_tools/satsync.py:2254
msgid "synchronize to this step (man satellite-sync for more info)"
msgstr "このステップまで同期 (詳しくは man satellite-sync を参照)"

#: ../satellite_tools/satsync.py:2256
msgid "write complete data to tempfile before streaming to remainder of app"
msgstr ""
"アプリの残り部分にストリーミングする前にテンポラリファイルに完全なデータを書"
"き込む"

#: ../satellite_tools/satsync.py:2258
msgid "DEBUG ONLY: alternative path to digital system id"
msgstr "デバッグのみ: デジタルシステム ID への代替パス"

#: ../satellite_tools/satsync.py:2260
msgid "alternative email address(es) for sync output (--email option)"
msgstr "同期出力向けの代替電子メールアドレス (--email オプション)"

#: ../satellite_tools/satsync.py:2262
msgid "do not remove rpms when importing from local dump"
msgstr "ローカルダンプからの取り込み時に rpm を削除しない"

#: ../satellite_tools/satsync.py:2264
msgid ""
"the fully qualified domain name of the master Satellite. Valid with --mount-"
"point only. Required if you want to import org data and channel permissions."
msgstr ""
"マスター Satellite の完全修飾ドメイン名です。 --mount-point と併用した場合に"
"のみ有効です。組織データとチャンネル許可を取り込みたい場合には必要です。"

#: ../satellite_tools/satsync.py:2274
#, python-format
msgid "ERROR: these arguments make no sense in this context (try --help): %s"
msgstr ""
"エラー: これらのパラメータは、この状況下では意味がありません (詳しくは --"
"help を参照): %s"

#. An SQL error is fatal... crash and burn
#: ../satellite_tools/satsync.py:2286
#, python-format
msgid "ERROR: Can't connect to the database: %s"
msgstr "エラー: データベースに接続できません: %s"

#: ../satellite_tools/satsync.py:2287
msgid "ERROR: Check if your database is running."
msgstr "エラー: データベースが動作しているかどうかご確認ください。"

#: ../satellite_tools/satsync.py:2322
#, python-format
msgid "ERROR: --debug-level takes an in integer value within the range %s."
msgstr "エラー: --debug-level には %s の範囲内の整数値を指定します。"

#: ../satellite_tools/satsync.py:2324
msgid "  0  - little logging/messaging."
msgstr "  0  - ごくわずかなログ／メッセージのみ。"

#: ../satellite_tools/satsync.py:2325
msgid "  1  - minimal logging/messaging."
msgstr "  1  - 最小限のログ／メッセージのみ。"

#: ../satellite_tools/satsync.py:2326
msgid "  2  - normal level of logging/messaging."
msgstr "  2  - 通常レベルのログ／メッセージ。"

#: ../satellite_tools/satsync.py:2327
msgid "  3  - lots of logging/messaging."
msgstr "  3  - 多くのログ／メッセージ。"

#: ../satellite_tools/satsync.py:2328
msgid "  4+ - excessive logging/messaging."
msgstr "  4+ - 非常に多くのログ／メッセージ。"

#: ../satellite_tools/satsync.py:2341
msgid "ERROR: The --master option is only valid with the --mount-point option"
msgstr ""
"エラー: --master オプションは --mount-point オプションと併用した場合にのみ有"
"効です"

#: ../satellite_tools/satsync.py:2351
#, python-format
msgid "ERROR: Unable to lookup Org Id %s"
msgstr "エラー: 組織 ID %s を参照できません"

#: ../satellite_tools/satsync.py:2360
msgid ""
"WARNING: --list-channels option overrides any --step option. --step ignored."
msgstr ""
"警告: --list-channels オプションは --step オプションを上書きしてしまいます。 "
"--step 側が無視されます。"

#: ../satellite_tools/satsync.py:2375
#, python-format
msgid ""
"ERROR: '%s' is not a valid step. See 'man mgr-inter-sync' for more detail."
msgstr ""
"エラー: '%s' のステップが正しくありません。詳しくは 'man mgr-inter-sync' をお"
"読みください。"

#: ../satellite_tools/satsync.py:2407
msgid ""
"ERROR: No channels currently imported; try mgr-inter-sync --list-channels; "
"then mgr-inter-sync -c chn0 -c chn1..."
msgstr ""
"エラー: 現時点では何もチャンネルを取り込んでいません。 mgr-inter-sync --list-"
"channels を実行したあと mgr-inter-sync -c chn0 -c chn1... のように実行してく"
"ださい。"

#. int(None) --> TypeError
#. int('a')  --> ValueError
#: ../satellite_tools/satsync.py:2457 ../satellite_tools/satsync.py:2461
msgid "ERROR: --batch-size must have a value within the range: 1..50"
msgstr "エラー: --batch-size の値は 1..50 までの値でなければなりません"

#: ../satellite_tools/satsync.py:2469
#, python-format
msgid "ERROR: no such directory %s"
msgstr "エラー: そのようなディレクトリはありません %s"

#: ../satellite_tools/satsync.py:2474
msgid "Error Codes: Returned codes means:"
msgstr "エラーコード: 返された値の意味は下記のとおりです:"

#: ../satellite_tools/satsync.py:2475
msgid " -1  - Could not lock file or KeyboardInterrupt or SystemExit"
msgstr ""
" -1  - ファイルをロックできなかったか、キーボード割り込みやシステムの終了が発"
"生しています"

#: ../satellite_tools/satsync.py:2476
msgid "  0  - User interrupted or intentional exit"
msgstr "  0  - ユーザ側での割り込みか終了指示が行なわれました"

#: ../satellite_tools/satsync.py:2477
msgid "  1  - attempting to run more than one instance of mgr-inter-sync."
msgstr "  1  - mgr-inter-sync のインスタンスを複数個実行しようとしています。"

#: ../satellite_tools/satsync.py:2478
msgid "  2  - Unable to find synchronization tools."
msgstr "  2  - 同期ツールが見つかりませんでした。"

#: ../satellite_tools/satsync.py:2479
msgid "  3  - a general socket exception occurred"
msgstr "  3  - 一般的なソケット例外が発生しました"

#: ../satellite_tools/satsync.py:2480
msgid "  4  - an SSL error occurred. Recheck your SSL settings."
msgstr "  4  - SSL エラーが発生しました。 SSL の設定を再確認してください。"

#: ../satellite_tools/satsync.py:2481
msgid "  5  - ISS error"
msgstr "  5  - ISS エラー"

#: ../satellite_tools/satsync.py:2482
msgid "  6  - unhandled exception occurred"
msgstr "  6  - ハンドルされていない例外が発生しました"

#: ../satellite_tools/satsync.py:2483
msgid "  7  - unknown sync error"
msgstr "  7  - 未知の同期エラーです"

#: ../satellite_tools/satsync.py:2484
msgid "  8  - ERROR: must be root to execute"
msgstr "  8  - エラー: 実行するには root でなければなりません"

#: ../satellite_tools/satsync.py:2485
msgid "  9  - rpclib fault during synchronization init"
msgstr "  9  - 同期の準備時に rpclib の例外が発生しました"

#: ../satellite_tools/satsync.py:2486
msgid "  10 - synchronization init error"
msgstr "  10 - 同期の準備時にエラーが発生しました"

#: ../satellite_tools/satsync.py:2487
msgid "  11 - Error parsing XML stream"
msgstr "  11 - XML ストリームの処理時にエラーが発生しました"

#: ../satellite_tools/satsync.py:2488
msgid "  12 - Channel do not exist"
msgstr "  12 - チャンネルが存在していません"

#: ../satellite_tools/satsync.py:2489
msgid "  13 - SQL error during importing package metadata"
msgstr "  13 - パッケージのメタデータを処理する際に SQL エラーが発生しました"

#: ../satellite_tools/satsync.py:2490
msgid "  14 - SQL error during linking channel packages"
msgstr "  14 - チャンネルパッケージのリンク時に SQL エラーが発生しました"

#: ../satellite_tools/satsync.py:2491
msgid "  15 - SQL error during xml processing"
msgstr "  15 - XML 処理時に SQL エラーが発生しました"

#: ../satellite_tools/satsync.py:2492
msgid "  16 - server.mount_point not set in the configuration file"
msgstr "  16 - 設定ファイル内で server.mount_point が設定されていません"

#: ../satellite_tools/satsync.py:2493
msgid ""
"  17 - SQL error during retrieving the channels already imported in the SUSE "
"Manager database"
msgstr ""
"  17 - SUSE Manager データベース内に既に取り込まれているチャンネルを取得する"
"際に、 SQL エラーが発生しました"

#: ../satellite_tools/satsync.py:2494
msgid "  18 - Wrong db connection string in rhn.conf"
msgstr "  18 - rhn.conf 内の DB 接続文字列が正しくありません"

#: ../satellite_tools/satsync.py:2495
msgid "  19 - Bad arguments"
msgstr "  19 - パラメータが正しくありません"

#: ../satellite_tools/satsync.py:2496
msgid "  20 - Could not connect to db."
msgstr "  20 - DB に接続できませんでした。"

#: ../satellite_tools/satsync.py:2497
msgid "  21 - Bad debug level"
msgstr "  21 - デバッグレベルが正しくありません"

#: ../satellite_tools/satsync.py:2498
msgid "  22 - Not valid step"
msgstr "  22 - ステップが正しくありません"

#: ../satellite_tools/satsync.py:2499
msgid "  24 - no such file"
msgstr "  24 - そのようなファイルはありません"

#: ../satellite_tools/satsync.py:2500
msgid "  25 - no such directory"
msgstr "  25 - そのようなディレクトリはありません"

#: ../satellite_tools/satsync.py:2501
msgid "  26 - mount_point does not exist"
msgstr "  26 - mount_point が存在しません"

#: ../satellite_tools/satsync.py:2502
msgid "  27 - No such org"
msgstr "  27 - そのような組織はありません"

#: ../satellite_tools/satsync.py:2503
msgid "  28 - error: --master is only valid with --mount-point"
msgstr ""
"  28 - エラー: --master は --mount-point とともに指定した場合にのみ有効です"

#: ../satellite_tools/satsync.py:2510
#, python-format
msgid "ERROR: unknown dump version, try one of %s"
msgstr "エラー: 未知のダンプバージョンです。 %s のいずれかをお試しください"

#~ msgid "Red Hat Satellite Welcome Message"
#~ msgstr "Red Hat Satellite のようこそメッセージ"
